{
 "cells": [
  {
   "cell_type": "code",
   "execution_count": 1,
   "metadata": {},
   "outputs": [
    {
     "ename": "ClientError",
     "evalue": "An error occurred (AccessDenied) when calling the GetObject operation: User: arn:aws:iam::193789491982:user/mlops_user is not authorized to perform: s3:GetObject on resource: \"arn:aws:s3:::emailclassification/complaints_processed.csv\" with an explicit deny in an identity-based policy",
     "output_type": "error",
     "traceback": [
      "\u001b[1;31m---------------------------------------------------------------------------\u001b[0m",
      "\u001b[1;31mClientError\u001b[0m                               Traceback (most recent call last)",
      "Cell \u001b[1;32mIn[1], line 16\u001b[0m\n\u001b[0;32m     13\u001b[0m file_key \u001b[38;5;241m=\u001b[39m \u001b[38;5;124m'\u001b[39m\u001b[38;5;124mcomplaints_processed.csv\u001b[39m\u001b[38;5;124m'\u001b[39m\n\u001b[0;32m     15\u001b[0m \u001b[38;5;66;03m# Get the object\u001b[39;00m\n\u001b[1;32m---> 16\u001b[0m obj \u001b[38;5;241m=\u001b[39m \u001b[43ms3\u001b[49m\u001b[38;5;241;43m.\u001b[39;49m\u001b[43mget_object\u001b[49m\u001b[43m(\u001b[49m\u001b[43mBucket\u001b[49m\u001b[38;5;241;43m=\u001b[39;49m\u001b[43mbucket_name\u001b[49m\u001b[43m,\u001b[49m\u001b[43m \u001b[49m\u001b[43mKey\u001b[49m\u001b[38;5;241;43m=\u001b[39;49m\u001b[43mfile_key\u001b[49m\u001b[43m)\u001b[49m\n\u001b[0;32m     18\u001b[0m \u001b[38;5;66;03m# Read data into a pandas DataFrame\u001b[39;00m\n\u001b[0;32m     19\u001b[0m df \u001b[38;5;241m=\u001b[39m pd\u001b[38;5;241m.\u001b[39mread_csv(StringIO(obj[\u001b[38;5;124m'\u001b[39m\u001b[38;5;124mBody\u001b[39m\u001b[38;5;124m'\u001b[39m]\u001b[38;5;241m.\u001b[39mread()\u001b[38;5;241m.\u001b[39mdecode(\u001b[38;5;124m'\u001b[39m\u001b[38;5;124mutf-8\u001b[39m\u001b[38;5;124m'\u001b[39m)))\n",
      "File \u001b[1;32mc:\\Users\\98912\\.conda\\envs\\env_email\\Lib\\site-packages\\botocore\\client.py:565\u001b[0m, in \u001b[0;36mClientCreator._create_api_method.<locals>._api_call\u001b[1;34m(self, *args, **kwargs)\u001b[0m\n\u001b[0;32m    561\u001b[0m     \u001b[38;5;28;01mraise\u001b[39;00m \u001b[38;5;167;01mTypeError\u001b[39;00m(\n\u001b[0;32m    562\u001b[0m         \u001b[38;5;124mf\u001b[39m\u001b[38;5;124m\"\u001b[39m\u001b[38;5;132;01m{\u001b[39;00mpy_operation_name\u001b[38;5;132;01m}\u001b[39;00m\u001b[38;5;124m() only accepts keyword arguments.\u001b[39m\u001b[38;5;124m\"\u001b[39m\n\u001b[0;32m    563\u001b[0m     )\n\u001b[0;32m    564\u001b[0m \u001b[38;5;66;03m# The \"self\" in this scope is referring to the BaseClient.\u001b[39;00m\n\u001b[1;32m--> 565\u001b[0m \u001b[38;5;28;01mreturn\u001b[39;00m \u001b[38;5;28;43mself\u001b[39;49m\u001b[38;5;241;43m.\u001b[39;49m\u001b[43m_make_api_call\u001b[49m\u001b[43m(\u001b[49m\u001b[43moperation_name\u001b[49m\u001b[43m,\u001b[49m\u001b[43m \u001b[49m\u001b[43mkwargs\u001b[49m\u001b[43m)\u001b[49m\n",
      "File \u001b[1;32mc:\\Users\\98912\\.conda\\envs\\env_email\\Lib\\site-packages\\botocore\\client.py:1017\u001b[0m, in \u001b[0;36mBaseClient._make_api_call\u001b[1;34m(self, operation_name, api_params)\u001b[0m\n\u001b[0;32m   1013\u001b[0m     error_code \u001b[38;5;241m=\u001b[39m error_info\u001b[38;5;241m.\u001b[39mget(\u001b[38;5;124m\"\u001b[39m\u001b[38;5;124mQueryErrorCode\u001b[39m\u001b[38;5;124m\"\u001b[39m) \u001b[38;5;129;01mor\u001b[39;00m error_info\u001b[38;5;241m.\u001b[39mget(\n\u001b[0;32m   1014\u001b[0m         \u001b[38;5;124m\"\u001b[39m\u001b[38;5;124mCode\u001b[39m\u001b[38;5;124m\"\u001b[39m\n\u001b[0;32m   1015\u001b[0m     )\n\u001b[0;32m   1016\u001b[0m     error_class \u001b[38;5;241m=\u001b[39m \u001b[38;5;28mself\u001b[39m\u001b[38;5;241m.\u001b[39mexceptions\u001b[38;5;241m.\u001b[39mfrom_code(error_code)\n\u001b[1;32m-> 1017\u001b[0m     \u001b[38;5;28;01mraise\u001b[39;00m error_class(parsed_response, operation_name)\n\u001b[0;32m   1018\u001b[0m \u001b[38;5;28;01melse\u001b[39;00m:\n\u001b[0;32m   1019\u001b[0m     \u001b[38;5;28;01mreturn\u001b[39;00m parsed_response\n",
      "\u001b[1;31mClientError\u001b[0m: An error occurred (AccessDenied) when calling the GetObject operation: User: arn:aws:iam::193789491982:user/mlops_user is not authorized to perform: s3:GetObject on resource: \"arn:aws:s3:::emailclassification/complaints_processed.csv\" with an explicit deny in an identity-based policy"
     ]
    }
   ],
   "source": [
    "import boto3\n",
    "import pandas as pd\n",
    "from io import StringIO\n",
    "\n",
    "# Initialize a session using Amazon S3\n",
    "s3 = boto3.client('s3', \n",
    "                  aws_access_key_id='AKIAS2HWA7MHAHBSU6IX', \n",
    "                  aws_secret_access_key='BFUwNass+/dqRvqWdxrfuUD9pSq1GcdYpE8W/k/E', \n",
    "                  region_name='eu-central-1')\n",
    "\n",
    "# Specify your bucket and file key\n",
    "bucket_name = 'emailclassification'\n",
    "file_key = 'complaints_processed.csv'\n",
    "\n",
    "# Get the object\n",
    "obj = s3.get_object(Bucket=bucket_name, Key=file_key)\n",
    "\n",
    "# Read data into a pandas DataFrame\n",
    "df = pd.read_csv(StringIO(obj['Body'].read().decode('utf-8')))\n",
    "\n",
    "# Display the DataFrame\n",
    "print(df)\n"
   ]
  }
 ],
 "metadata": {
  "kernelspec": {
   "display_name": "env_email",
   "language": "python",
   "name": "python3"
  },
  "language_info": {
   "codemirror_mode": {
    "name": "ipython",
    "version": 3
   },
   "file_extension": ".py",
   "mimetype": "text/x-python",
   "name": "python",
   "nbconvert_exporter": "python",
   "pygments_lexer": "ipython3",
   "version": "3.12.7"
  }
 },
 "nbformat": 4,
 "nbformat_minor": 2
}
